[2023-10-28 03:03:48,749] {taskinstance.py:1179} INFO - Dependencies all met for <TaskInstance: update_data.update_data scheduled__2023-10-25T15:30:00+00:00 [queued]>
[2023-10-28 03:03:48,761] {taskinstance.py:1179} INFO - Dependencies all met for <TaskInstance: update_data.update_data scheduled__2023-10-25T15:30:00+00:00 [queued]>
[2023-10-28 03:03:48,761] {taskinstance.py:1376} INFO - 
--------------------------------------------------------------------------------
[2023-10-28 03:03:48,761] {taskinstance.py:1377} INFO - Starting attempt 7 of 11
[2023-10-28 03:03:48,761] {taskinstance.py:1378} INFO - 
--------------------------------------------------------------------------------
[2023-10-28 03:03:48,778] {taskinstance.py:1397} INFO - Executing <Task(BashOperator): update_data> on 2023-10-25 15:30:00+00:00
[2023-10-28 03:03:48,783] {standard_task_runner.py:52} INFO - Started process 1053 to run task
[2023-10-28 03:03:48,786] {standard_task_runner.py:79} INFO - Running: ['***', 'tasks', 'run', 'update_data', 'update_data', 'scheduled__2023-10-25T15:30:00+00:00', '--job-id', '52', '--raw', '--subdir', 'DAGS_FOLDER/update_data_dag.py', '--cfg-path', '/tmp/tmpjij9ieh0', '--error-file', '/tmp/tmpgu959nim']
[2023-10-28 03:03:48,787] {standard_task_runner.py:80} INFO - Job 52: Subtask update_data
[2023-10-28 03:03:53,863] {task_command.py:371} INFO - Running <TaskInstance: update_data.update_data scheduled__2023-10-25T15:30:00+00:00 [running]> on host 9161207b4c08
[2023-10-28 03:03:53,942] {taskinstance.py:1591} INFO - Exporting the following env vars:
AIRFLOW_CTX_DAG_OWNER=Admin
AIRFLOW_CTX_DAG_ID=update_data
AIRFLOW_CTX_TASK_ID=update_data
AIRFLOW_CTX_EXECUTION_DATE=2023-10-25T15:30:00+00:00
AIRFLOW_CTX_TRY_NUMBER=7
AIRFLOW_CTX_DAG_RUN_ID=scheduled__2023-10-25T15:30:00+00:00
[2023-10-28 03:03:53,943] {subprocess.py:62} INFO - Tmp dir root location: 
 /tmp
[2023-10-28 03:03:53,944] {subprocess.py:74} INFO - Running command: ['bash', '-c', 'python3 update_data.py']
[2023-10-28 03:03:53,954] {subprocess.py:85} INFO - Output:
[2023-10-28 03:03:54,070] {subprocess.py:92} INFO - python3: can't open file 'update_data.py': [Errno 2] No such file or directory
[2023-10-28 03:03:54,073] {subprocess.py:96} INFO - Command exited with return code 2
[2023-10-28 03:03:54,091] {taskinstance.py:1909} ERROR - Task failed with exception
Traceback (most recent call last):
  File "/home/airflow/.local/lib/python3.7/site-packages/airflow/operators/bash.py", line 195, in execute
    f'Bash command failed. The command returned a non-zero exit code {result.exit_code}.'
airflow.exceptions.AirflowException: Bash command failed. The command returned a non-zero exit code 2.
[2023-10-28 03:03:54,095] {taskinstance.py:1420} INFO - Marking task as UP_FOR_RETRY. dag_id=update_data, task_id=update_data, execution_date=20231025T153000, start_date=20231028T030348, end_date=20231028T030354
[2023-10-28 03:03:54,109] {standard_task_runner.py:97} ERROR - Failed to execute job 52 for task update_data (Bash command failed. The command returned a non-zero exit code 2.; 1053)
[2023-10-28 03:03:54,144] {local_task_job.py:156} INFO - Task exited with return code 1
[2023-10-28 03:03:54,173] {local_task_job.py:273} INFO - 0 downstream tasks scheduled from follow-on schedule check
