[2023-10-31 01:22:51,489] {taskinstance.py:1179} INFO - Dependencies all met for <TaskInstance: update_data.update_data manual__2023-10-31T01:19:49.502595+00:00 [queued]>
[2023-10-31 01:22:51,502] {taskinstance.py:1179} INFO - Dependencies all met for <TaskInstance: update_data.update_data manual__2023-10-31T01:19:49.502595+00:00 [queued]>
[2023-10-31 01:22:51,503] {taskinstance.py:1376} INFO - 
--------------------------------------------------------------------------------
[2023-10-31 01:22:51,503] {taskinstance.py:1377} INFO - Starting attempt 2 of 11
[2023-10-31 01:22:51,503] {taskinstance.py:1378} INFO - 
--------------------------------------------------------------------------------
[2023-10-31 01:22:51,520] {taskinstance.py:1397} INFO - Executing <Task(BashOperator): update_data> on 2023-10-31 01:19:49.502595+00:00
[2023-10-31 01:22:51,525] {standard_task_runner.py:52} INFO - Started process 879 to run task
[2023-10-31 01:22:51,529] {standard_task_runner.py:79} INFO - Running: ['***', 'tasks', 'run', 'update_data', 'update_data', 'manual__2023-10-31T01:19:49.502595+00:00', '--job-id', '168', '--raw', '--subdir', 'DAGS_FOLDER/update_data_dag2.py', '--cfg-path', '/tmp/tmpf4grgyj3', '--error-file', '/tmp/tmpt1bl45fb']
[2023-10-31 01:22:51,530] {standard_task_runner.py:80} INFO - Job 168: Subtask update_data
[2023-10-31 01:22:51,617] {task_command.py:371} INFO - Running <TaskInstance: update_data.update_data manual__2023-10-31T01:19:49.502595+00:00 [running]> on host d7c4bbae6ce0
[2023-10-31 01:22:51,706] {taskinstance.py:1591} INFO - Exporting the following env vars:
AIRFLOW_CTX_DAG_OWNER=Admin
AIRFLOW_CTX_DAG_ID=update_data
AIRFLOW_CTX_TASK_ID=update_data
AIRFLOW_CTX_EXECUTION_DATE=2023-10-31T01:19:49.502595+00:00
AIRFLOW_CTX_TRY_NUMBER=2
AIRFLOW_CTX_DAG_RUN_ID=manual__2023-10-31T01:19:49.502595+00:00
[2023-10-31 01:22:51,707] {subprocess.py:62} INFO - Tmp dir root location: 
 /tmp
[2023-10-31 01:22:51,708] {subprocess.py:74} INFO - Running command: ['bash', '-c', 'docker start update_data']
[2023-10-31 01:22:51,719] {subprocess.py:85} INFO - Output:
[2023-10-31 01:22:51,721] {subprocess.py:92} INFO - bash: line 1: docker: command not found
[2023-10-31 01:22:51,721] {subprocess.py:96} INFO - Command exited with return code 127
[2023-10-31 01:22:51,740] {taskinstance.py:1909} ERROR - Task failed with exception
Traceback (most recent call last):
  File "/home/airflow/.local/lib/python3.7/site-packages/airflow/operators/bash.py", line 195, in execute
    f'Bash command failed. The command returned a non-zero exit code {result.exit_code}.'
airflow.exceptions.AirflowException: Bash command failed. The command returned a non-zero exit code 127.
[2023-10-31 01:22:51,745] {taskinstance.py:1420} INFO - Marking task as UP_FOR_RETRY. dag_id=update_data, task_id=update_data, execution_date=20231031T011949, start_date=20231031T012251, end_date=20231031T012251
[2023-10-31 01:22:51,759] {standard_task_runner.py:97} ERROR - Failed to execute job 168 for task update_data (Bash command failed. The command returned a non-zero exit code 127.; 879)
[2023-10-31 01:22:51,783] {local_task_job.py:156} INFO - Task exited with return code 1
[2023-10-31 01:22:51,821] {local_task_job.py:273} INFO - 0 downstream tasks scheduled from follow-on schedule check
