[2023-10-28 02:36:57,088] {taskinstance.py:1179} INFO - Dependencies all met for <TaskInstance: my_dag.update_data manual__2023-10-28T02:36:55.793679+00:00 [queued]>
[2023-10-28 02:36:57,100] {taskinstance.py:1179} INFO - Dependencies all met for <TaskInstance: my_dag.update_data manual__2023-10-28T02:36:55.793679+00:00 [queued]>
[2023-10-28 02:36:57,100] {taskinstance.py:1376} INFO - 
--------------------------------------------------------------------------------
[2023-10-28 02:36:57,101] {taskinstance.py:1377} INFO - Starting attempt 1 of 11
[2023-10-28 02:36:57,101] {taskinstance.py:1378} INFO - 
--------------------------------------------------------------------------------
[2023-10-28 02:36:57,117] {taskinstance.py:1397} INFO - Executing <Task(BashOperator): update_data> on 2023-10-28 02:36:55.793679+00:00
[2023-10-28 02:36:57,121] {standard_task_runner.py:52} INFO - Started process 151 to run task
[2023-10-28 02:36:57,125] {standard_task_runner.py:79} INFO - Running: ['***', 'tasks', 'run', 'my_dag', 'update_data', 'manual__2023-10-28T02:36:55.793679+00:00', '--job-id', '36', '--raw', '--subdir', 'DAGS_FOLDER/update_data_dag.py', '--cfg-path', '/tmp/tmpxtj_qrrm', '--error-file', '/tmp/tmpp1tlzm9d']
[2023-10-28 02:36:57,125] {standard_task_runner.py:80} INFO - Job 36: Subtask update_data
[2023-10-28 02:36:57,196] {task_command.py:371} INFO - Running <TaskInstance: my_dag.update_data manual__2023-10-28T02:36:55.793679+00:00 [running]> on host 9161207b4c08
[2023-10-28 02:36:57,277] {taskinstance.py:1591} INFO - Exporting the following env vars:
AIRFLOW_CTX_DAG_OWNER=Admin
AIRFLOW_CTX_DAG_ID=my_dag
AIRFLOW_CTX_TASK_ID=update_data
AIRFLOW_CTX_EXECUTION_DATE=2023-10-28T02:36:55.793679+00:00
AIRFLOW_CTX_TRY_NUMBER=1
AIRFLOW_CTX_DAG_RUN_ID=manual__2023-10-28T02:36:55.793679+00:00
[2023-10-28 02:36:57,278] {subprocess.py:62} INFO - Tmp dir root location: 
 /tmp
[2023-10-28 02:36:57,279] {subprocess.py:74} INFO - Running command: ['bash', '-c', 'python3 update_data.py']
[2023-10-28 02:36:57,289] {subprocess.py:85} INFO - Output:
[2023-10-28 02:36:57,406] {subprocess.py:92} INFO - python3: can't open file 'update_data.py': [Errno 2] No such file or directory
[2023-10-28 02:36:57,410] {subprocess.py:96} INFO - Command exited with return code 2
[2023-10-28 02:36:57,428] {taskinstance.py:1909} ERROR - Task failed with exception
Traceback (most recent call last):
  File "/home/airflow/.local/lib/python3.7/site-packages/airflow/operators/bash.py", line 195, in execute
    f'Bash command failed. The command returned a non-zero exit code {result.exit_code}.'
airflow.exceptions.AirflowException: Bash command failed. The command returned a non-zero exit code 2.
[2023-10-28 02:36:57,432] {taskinstance.py:1420} INFO - Marking task as UP_FOR_RETRY. dag_id=my_dag, task_id=update_data, execution_date=20231028T023655, start_date=20231028T023657, end_date=20231028T023657
[2023-10-28 02:36:57,446] {standard_task_runner.py:97} ERROR - Failed to execute job 36 for task update_data (Bash command failed. The command returned a non-zero exit code 2.; 151)
[2023-10-28 02:36:57,457] {local_task_job.py:156} INFO - Task exited with return code 1
[2023-10-28 02:36:57,495] {local_task_job.py:273} INFO - 0 downstream tasks scheduled from follow-on schedule check
