[2023-11-01T04:54:53.935+0000] {taskinstance.py:1103} INFO - Dependencies all met for dep_context=non-requeueable deps ti=<TaskInstance: predict_dag.predict_task manual__2023-11-01T04:44:33.032328+00:00 [queued]>
[2023-11-01T04:54:53.946+0000] {taskinstance.py:1103} INFO - Dependencies all met for dep_context=requeueable deps ti=<TaskInstance: predict_dag.predict_task manual__2023-11-01T04:44:33.032328+00:00 [queued]>
[2023-11-01T04:54:53.946+0000] {taskinstance.py:1308} INFO - Starting attempt 3 of 11
[2023-11-01T04:54:53.966+0000] {taskinstance.py:1327} INFO - Executing <Task(predictOperator): predict_task> on 2023-11-01 04:44:33.032328+00:00
[2023-11-01T04:54:53.975+0000] {standard_task_runner.py:57} INFO - Started process 661 to run task
[2023-11-01T04:54:53.980+0000] {standard_task_runner.py:84} INFO - Running: ['***', 'tasks', 'run', 'predict_dag', 'predict_task', 'manual__2023-11-01T04:44:33.032328+00:00', '--job-id', '23', '--raw', '--subdir', 'DAGS_FOLDER/predict_dag.py', '--cfg-path', '/tmp/tmp22uqy4v6']
[2023-11-01T04:54:53.985+0000] {standard_task_runner.py:85} INFO - Job 23: Subtask predict_task
[2023-11-01T04:54:54.060+0000] {task_command.py:410} INFO - Running <TaskInstance: predict_dag.predict_task manual__2023-11-01T04:44:33.032328+00:00 [running]> on host 699e1a4b8602
[2023-11-01T04:54:54.175+0000] {taskinstance.py:1547} INFO - Exporting env vars: AIRFLOW_CTX_DAG_OWNER='Admin' AIRFLOW_CTX_DAG_ID='predict_dag' AIRFLOW_CTX_TASK_ID='predict_task' AIRFLOW_CTX_EXECUTION_DATE='2023-11-01T04:44:33.032328+00:00' AIRFLOW_CTX_TRY_NUMBER='3' AIRFLOW_CTX_DAG_RUN_ID='manual__2023-11-01T04:44:33.032328+00:00'
[2023-11-01T04:54:54.177+0000] {predict_operator.py:28} INFO - 데이터 업데이트 스크립트를 실행합니다: /opt/***/dags/pythonfile/predict.py
[2023-11-01T04:55:00.867+0000] {predict_operator.py:34} ERROR - 데이터 업데이트 스크립트 실행 중 오류 발생: Command '['python', '/opt/airflow/dags/pythonfile/predict.py']' returned non-zero exit status 1.
[2023-11-01T04:55:00.869+0000] {taskinstance.py:1824} ERROR - Task failed with exception
Traceback (most recent call last):
  File "/opt/airflow/dags/custom_operators/predict_operator.py", line 35, in execute
    raise e
  File "/opt/airflow/dags/custom_operators/predict_operator.py", line 31, in execute
    subprocess.run(['python', self.script_path], check=True)
  File "/usr/local/lib/python3.7/subprocess.py", line 512, in run
    output=stdout, stderr=stderr)
subprocess.CalledProcessError: Command '['python', '/opt/airflow/dags/pythonfile/predict.py']' returned non-zero exit status 1.
[2023-11-01T04:55:00.884+0000] {taskinstance.py:1350} INFO - Marking task as UP_FOR_RETRY. dag_id=predict_dag, task_id=predict_task, execution_date=20231101T044433, start_date=20231101T045453, end_date=20231101T045500
[2023-11-01T04:55:00.902+0000] {standard_task_runner.py:109} ERROR - Failed to execute job 23 for task predict_task (Command '['python', '/opt/airflow/dags/pythonfile/predict.py']' returned non-zero exit status 1.; 661)
[2023-11-01T04:55:00.951+0000] {local_task_job_runner.py:225} INFO - Task exited with return code 1
[2023-11-01T04:55:00.974+0000] {taskinstance.py:2653} INFO - 0 downstream tasks scheduled from follow-on schedule check
