[2023-10-31 01:15:31,962] {taskinstance.py:1179} INFO - Dependencies all met for <TaskInstance: update_data.update_data manual__2023-10-31T01:09:23.155569+00:00 [queued]>
[2023-10-31 01:15:31,975] {taskinstance.py:1179} INFO - Dependencies all met for <TaskInstance: update_data.update_data manual__2023-10-31T01:09:23.155569+00:00 [queued]>
[2023-10-31 01:15:31,975] {taskinstance.py:1376} INFO - 
--------------------------------------------------------------------------------
[2023-10-31 01:15:31,975] {taskinstance.py:1377} INFO - Starting attempt 3 of 11
[2023-10-31 01:15:31,975] {taskinstance.py:1378} INFO - 
--------------------------------------------------------------------------------
[2023-10-31 01:15:31,990] {taskinstance.py:1397} INFO - Executing <Task(BashOperator): update_data> on 2023-10-31 01:09:23.155569+00:00
[2023-10-31 01:15:31,995] {standard_task_runner.py:52} INFO - Started process 553 to run task
[2023-10-31 01:15:31,999] {standard_task_runner.py:79} INFO - Running: ['***', 'tasks', 'run', 'update_data', 'update_data', 'manual__2023-10-31T01:09:23.155569+00:00', '--job-id', '165', '--raw', '--subdir', 'DAGS_FOLDER/update_data_dag2.py', '--cfg-path', '/tmp/tmpg1o65zvo', '--error-file', '/tmp/tmp51rbeu8p']
[2023-10-31 01:15:32,000] {standard_task_runner.py:80} INFO - Job 165: Subtask update_data
[2023-10-31 01:15:32,075] {task_command.py:371} INFO - Running <TaskInstance: update_data.update_data manual__2023-10-31T01:09:23.155569+00:00 [running]> on host d7c4bbae6ce0
[2023-10-31 01:15:32,161] {taskinstance.py:1591} INFO - Exporting the following env vars:
AIRFLOW_CTX_DAG_OWNER=Admin
AIRFLOW_CTX_DAG_ID=update_data
AIRFLOW_CTX_TASK_ID=update_data
AIRFLOW_CTX_EXECUTION_DATE=2023-10-31T01:09:23.155569+00:00
AIRFLOW_CTX_TRY_NUMBER=3
AIRFLOW_CTX_DAG_RUN_ID=manual__2023-10-31T01:09:23.155569+00:00
[2023-10-31 01:15:32,162] {subprocess.py:62} INFO - Tmp dir root location: 
 /tmp
[2023-10-31 01:15:32,162] {subprocess.py:74} INFO - Running command: ['bash', '-c', 'docker start update_data']
[2023-10-31 01:15:32,172] {subprocess.py:85} INFO - Output:
[2023-10-31 01:15:32,174] {subprocess.py:92} INFO - bash: line 1: docker: command not found
[2023-10-31 01:15:32,175] {subprocess.py:96} INFO - Command exited with return code 127
[2023-10-31 01:15:32,193] {taskinstance.py:1909} ERROR - Task failed with exception
Traceback (most recent call last):
  File "/home/airflow/.local/lib/python3.7/site-packages/airflow/operators/bash.py", line 195, in execute
    f'Bash command failed. The command returned a non-zero exit code {result.exit_code}.'
airflow.exceptions.AirflowException: Bash command failed. The command returned a non-zero exit code 127.
[2023-10-31 01:15:32,197] {taskinstance.py:1420} INFO - Marking task as UP_FOR_RETRY. dag_id=update_data, task_id=update_data, execution_date=20231031T010923, start_date=20231031T011531, end_date=20231031T011532
[2023-10-31 01:15:32,210] {standard_task_runner.py:97} ERROR - Failed to execute job 165 for task update_data (Bash command failed. The command returned a non-zero exit code 127.; 553)
[2023-10-31 01:15:32,251] {local_task_job.py:156} INFO - Task exited with return code 1
[2023-10-31 01:15:32,288] {local_task_job.py:273} INFO - 0 downstream tasks scheduled from follow-on schedule check
