[2023-11-01T02:25:50.906+0000] {taskinstance.py:1103} INFO - Dependencies all met for dep_context=non-requeueable deps ti=<TaskInstance: data_update_dag.data_update_task manual__2023-11-01T02:25:49.441354+00:00 [queued]>
[2023-11-01T02:25:50.918+0000] {taskinstance.py:1103} INFO - Dependencies all met for dep_context=requeueable deps ti=<TaskInstance: data_update_dag.data_update_task manual__2023-11-01T02:25:49.441354+00:00 [queued]>
[2023-11-01T02:25:50.919+0000] {taskinstance.py:1308} INFO - Starting attempt 1 of 1
[2023-11-01T02:25:50.938+0000] {taskinstance.py:1327} INFO - Executing <Task(UpdateDataOperator): data_update_task> on 2023-11-01 02:25:49.441354+00:00
[2023-11-01T02:25:50.948+0000] {standard_task_runner.py:57} INFO - Started process 1747 to run task
[2023-11-01T02:25:50.954+0000] {standard_task_runner.py:84} INFO - Running: ['***', 'tasks', 'run', 'data_update_dag', 'data_update_task', 'manual__2023-11-01T02:25:49.441354+00:00', '--job-id', '11', '--raw', '--subdir', 'DAGS_FOLDER/update_dag.py', '--cfg-path', '/tmp/tmp4a_s27ov']
[2023-11-01T02:25:50.959+0000] {standard_task_runner.py:85} INFO - Job 11: Subtask data_update_task
[2023-11-01T02:25:51.029+0000] {task_command.py:410} INFO - Running <TaskInstance: data_update_dag.data_update_task manual__2023-11-01T02:25:49.441354+00:00 [running]> on host 4c3d82a97f2f
[2023-11-01T02:25:51.140+0000] {taskinstance.py:1547} INFO - Exporting env vars: AIRFLOW_CTX_DAG_OWNER='Admin' AIRFLOW_CTX_DAG_ID='data_update_dag' AIRFLOW_CTX_TASK_ID='data_update_task' AIRFLOW_CTX_EXECUTION_DATE='2023-11-01T02:25:49.441354+00:00' AIRFLOW_CTX_TRY_NUMBER='1' AIRFLOW_CTX_DAG_RUN_ID='manual__2023-11-01T02:25:49.441354+00:00'
[2023-11-01T02:25:51.142+0000] {update_operator.py:28} INFO - 데이터 업데이트 스크립트를 실행합니다: /opt/***/dags
[2023-11-01T02:25:51.296+0000] {update_operator.py:34} ERROR - 데이터 업데이트 스크립트 실행 중 오류 발생: Command '['python', '/opt/airflow/dags']' returned non-zero exit status 1.
[2023-11-01T02:25:51.298+0000] {taskinstance.py:1824} ERROR - Task failed with exception
Traceback (most recent call last):
  File "/opt/airflow/dags/update_operator.py", line 35, in execute
    raise e
  File "/opt/airflow/dags/update_operator.py", line 31, in execute
    subprocess.run(['python', self.script_path], check=True)
  File "/usr/local/lib/python3.7/subprocess.py", line 512, in run
    output=stdout, stderr=stderr)
subprocess.CalledProcessError: Command '['python', '/opt/airflow/dags']' returned non-zero exit status 1.
[2023-11-01T02:25:51.313+0000] {taskinstance.py:1350} INFO - Marking task as FAILED. dag_id=data_update_dag, task_id=data_update_task, execution_date=20231101T022549, start_date=20231101T022550, end_date=20231101T022551
[2023-11-01T02:25:51.330+0000] {standard_task_runner.py:109} ERROR - Failed to execute job 11 for task data_update_task (Command '['python', '/opt/airflow/dags']' returned non-zero exit status 1.; 1747)
[2023-11-01T02:25:51.366+0000] {local_task_job_runner.py:225} INFO - Task exited with return code 1
[2023-11-01T02:25:51.396+0000] {taskinstance.py:2653} INFO - 0 downstream tasks scheduled from follow-on schedule check
