[2023-10-28 03:05:01,034] {taskinstance.py:1179} INFO - Dependencies all met for <TaskInstance: predict.predict scheduled__2023-10-25T15:00:00+00:00 [queued]>
[2023-10-28 03:05:01,046] {taskinstance.py:1179} INFO - Dependencies all met for <TaskInstance: predict.predict scheduled__2023-10-25T15:00:00+00:00 [queued]>
[2023-10-28 03:05:01,047] {taskinstance.py:1376} INFO - 
--------------------------------------------------------------------------------
[2023-10-28 03:05:01,047] {taskinstance.py:1377} INFO - Starting attempt 2 of 11
[2023-10-28 03:05:01,047] {taskinstance.py:1378} INFO - 
--------------------------------------------------------------------------------
[2023-10-28 03:05:01,063] {taskinstance.py:1397} INFO - Executing <Task(BashOperator): predict> on 2023-10-25 15:00:00+00:00
[2023-10-28 03:05:01,068] {standard_task_runner.py:52} INFO - Started process 1101 to run task
[2023-10-28 03:05:01,072] {standard_task_runner.py:79} INFO - Running: ['***', 'tasks', 'run', 'predict', 'predict', 'scheduled__2023-10-25T15:00:00+00:00', '--job-id', '53', '--raw', '--subdir', 'DAGS_FOLDER/predict_dag.py', '--cfg-path', '/tmp/tmpztn1jgvi', '--error-file', '/tmp/tmpt6gi03kz']
[2023-10-28 03:05:01,072] {standard_task_runner.py:80} INFO - Job 53: Subtask predict
[2023-10-28 03:05:01,145] {task_command.py:371} INFO - Running <TaskInstance: predict.predict scheduled__2023-10-25T15:00:00+00:00 [running]> on host 9161207b4c08
[2023-10-28 03:05:01,228] {taskinstance.py:1591} INFO - Exporting the following env vars:
AIRFLOW_CTX_DAG_OWNER=Admin
AIRFLOW_CTX_DAG_ID=predict
AIRFLOW_CTX_TASK_ID=predict
AIRFLOW_CTX_EXECUTION_DATE=2023-10-25T15:00:00+00:00
AIRFLOW_CTX_TRY_NUMBER=2
AIRFLOW_CTX_DAG_RUN_ID=scheduled__2023-10-25T15:00:00+00:00
[2023-10-28 03:05:01,229] {subprocess.py:62} INFO - Tmp dir root location: 
 /tmp
[2023-10-28 03:05:01,230] {subprocess.py:74} INFO - Running command: ['bash', '-c', 'python3 predict.py']
[2023-10-28 03:05:01,240] {subprocess.py:85} INFO - Output:
[2023-10-28 03:05:01,359] {subprocess.py:92} INFO - python3: can't open file 'predict.py': [Errno 2] No such file or directory
[2023-10-28 03:05:01,363] {subprocess.py:96} INFO - Command exited with return code 2
[2023-10-28 03:05:01,382] {taskinstance.py:1909} ERROR - Task failed with exception
Traceback (most recent call last):
  File "/home/airflow/.local/lib/python3.7/site-packages/airflow/operators/bash.py", line 195, in execute
    f'Bash command failed. The command returned a non-zero exit code {result.exit_code}.'
airflow.exceptions.AirflowException: Bash command failed. The command returned a non-zero exit code 2.
[2023-10-28 03:05:01,386] {taskinstance.py:1420} INFO - Marking task as UP_FOR_RETRY. dag_id=predict, task_id=predict, execution_date=20231025T150000, start_date=20231028T030501, end_date=20231028T030501
[2023-10-28 03:05:01,399] {standard_task_runner.py:97} ERROR - Failed to execute job 53 for task predict (Bash command failed. The command returned a non-zero exit code 2.; 1101)
[2023-10-28 03:05:01,443] {local_task_job.py:156} INFO - Task exited with return code 1
[2023-10-28 03:05:01,480] {local_task_job.py:273} INFO - 0 downstream tasks scheduled from follow-on schedule check
