[2023-10-30 00:14:19,408] {taskinstance.py:1179} INFO - Dependencies all met for <TaskInstance: predict.predict scheduled__2023-10-25T15:00:00+00:00 [queued]>
[2023-10-30 00:14:19,419] {taskinstance.py:1179} INFO - Dependencies all met for <TaskInstance: predict.predict scheduled__2023-10-25T15:00:00+00:00 [queued]>
[2023-10-30 00:14:19,419] {taskinstance.py:1376} INFO - 
--------------------------------------------------------------------------------
[2023-10-30 00:14:19,419] {taskinstance.py:1377} INFO - Starting attempt 5 of 11
[2023-10-30 00:14:19,419] {taskinstance.py:1378} INFO - 
--------------------------------------------------------------------------------
[2023-10-30 00:14:19,440] {taskinstance.py:1397} INFO - Executing <Task(BashOperator): predict> on 2023-10-25 15:00:00+00:00
[2023-10-30 00:14:19,444] {standard_task_runner.py:52} INFO - Started process 330 to run task
[2023-10-30 00:14:19,452] {standard_task_runner.py:79} INFO - Running: ['***', 'tasks', 'run', 'predict', 'predict', 'scheduled__2023-10-25T15:00:00+00:00', '--job-id', '74', '--raw', '--subdir', 'DAGS_FOLDER/predict_dag.py', '--cfg-path', '/tmp/tmpfyg7t8d5', '--error-file', '/tmp/tmpob6vjq47']
[2023-10-30 00:14:19,452] {standard_task_runner.py:80} INFO - Job 74: Subtask predict
[2023-10-30 00:14:19,534] {task_command.py:371} INFO - Running <TaskInstance: predict.predict scheduled__2023-10-25T15:00:00+00:00 [running]> on host 9161207b4c08
[2023-10-30 00:14:19,625] {taskinstance.py:1591} INFO - Exporting the following env vars:
AIRFLOW_CTX_DAG_OWNER=Admin
AIRFLOW_CTX_DAG_ID=predict
AIRFLOW_CTX_TASK_ID=predict
AIRFLOW_CTX_EXECUTION_DATE=2023-10-25T15:00:00+00:00
AIRFLOW_CTX_TRY_NUMBER=5
AIRFLOW_CTX_DAG_RUN_ID=scheduled__2023-10-25T15:00:00+00:00
[2023-10-30 00:14:19,626] {subprocess.py:62} INFO - Tmp dir root location: 
 /tmp
[2023-10-30 00:14:19,626] {subprocess.py:74} INFO - Running command: ['bash', '-c', 'python3 predict.py']
[2023-10-30 00:14:19,636] {subprocess.py:85} INFO - Output:
[2023-10-30 00:14:19,762] {subprocess.py:92} INFO - python3: can't open file 'predict.py': [Errno 2] No such file or directory
[2023-10-30 00:14:19,766] {subprocess.py:96} INFO - Command exited with return code 2
[2023-10-30 00:14:19,786] {taskinstance.py:1909} ERROR - Task failed with exception
Traceback (most recent call last):
  File "/home/airflow/.local/lib/python3.7/site-packages/airflow/operators/bash.py", line 195, in execute
    f'Bash command failed. The command returned a non-zero exit code {result.exit_code}.'
airflow.exceptions.AirflowException: Bash command failed. The command returned a non-zero exit code 2.
[2023-10-30 00:14:19,794] {taskinstance.py:1420} INFO - Marking task as UP_FOR_RETRY. dag_id=predict, task_id=predict, execution_date=20231025T150000, start_date=20231030T001419, end_date=20231030T001419
[2023-10-30 00:14:19,808] {standard_task_runner.py:97} ERROR - Failed to execute job 74 for task predict (Bash command failed. The command returned a non-zero exit code 2.; 330)
[2023-10-30 00:14:19,819] {local_task_job.py:156} INFO - Task exited with return code 1
[2023-10-30 00:14:19,872] {local_task_job.py:273} INFO - 0 downstream tasks scheduled from follow-on schedule check
