[2023-10-30 00:18:21,458] {taskinstance.py:1179} INFO - Dependencies all met for <TaskInstance: update_data.update_data manual__2023-10-28T03:06:12.339983+00:00 [queued]>
[2023-10-30 00:18:21,470] {taskinstance.py:1179} INFO - Dependencies all met for <TaskInstance: update_data.update_data manual__2023-10-28T03:06:12.339983+00:00 [queued]>
[2023-10-30 00:18:21,470] {taskinstance.py:1376} INFO - 
--------------------------------------------------------------------------------
[2023-10-30 00:18:21,470] {taskinstance.py:1377} INFO - Starting attempt 6 of 11
[2023-10-30 00:18:21,470] {taskinstance.py:1378} INFO - 
--------------------------------------------------------------------------------
[2023-10-30 00:18:21,487] {taskinstance.py:1397} INFO - Executing <Task(BashOperator): update_data> on 2023-10-28 03:06:12.339983+00:00
[2023-10-30 00:18:21,491] {standard_task_runner.py:52} INFO - Started process 528 to run task
[2023-10-30 00:18:21,495] {standard_task_runner.py:79} INFO - Running: ['***', 'tasks', 'run', 'update_data', 'update_data', 'manual__2023-10-28T03:06:12.339983+00:00', '--job-id', '79', '--raw', '--subdir', 'DAGS_FOLDER/update_data_dag.py', '--cfg-path', '/tmp/tmpepiwanv0', '--error-file', '/tmp/tmp6fikiz3z']
[2023-10-30 00:18:21,495] {standard_task_runner.py:80} INFO - Job 79: Subtask update_data
[2023-10-30 00:18:21,560] {task_command.py:371} INFO - Running <TaskInstance: update_data.update_data manual__2023-10-28T03:06:12.339983+00:00 [running]> on host 9161207b4c08
[2023-10-30 00:18:21,636] {taskinstance.py:1591} INFO - Exporting the following env vars:
AIRFLOW_CTX_DAG_OWNER=Admin
AIRFLOW_CTX_DAG_ID=update_data
AIRFLOW_CTX_TASK_ID=update_data
AIRFLOW_CTX_EXECUTION_DATE=2023-10-28T03:06:12.339983+00:00
AIRFLOW_CTX_TRY_NUMBER=6
AIRFLOW_CTX_DAG_RUN_ID=manual__2023-10-28T03:06:12.339983+00:00
[2023-10-30 00:18:21,637] {subprocess.py:62} INFO - Tmp dir root location: 
 /tmp
[2023-10-30 00:18:21,638] {subprocess.py:74} INFO - Running command: ['bash', '-c', 'python3 update_data.py']
[2023-10-30 00:18:21,647] {subprocess.py:85} INFO - Output:
[2023-10-30 00:18:21,761] {subprocess.py:92} INFO - python3: can't open file 'update_data.py': [Errno 2] No such file or directory
[2023-10-30 00:18:21,765] {subprocess.py:96} INFO - Command exited with return code 2
[2023-10-30 00:18:21,782] {taskinstance.py:1909} ERROR - Task failed with exception
Traceback (most recent call last):
  File "/home/airflow/.local/lib/python3.7/site-packages/airflow/operators/bash.py", line 195, in execute
    f'Bash command failed. The command returned a non-zero exit code {result.exit_code}.'
airflow.exceptions.AirflowException: Bash command failed. The command returned a non-zero exit code 2.
[2023-10-30 00:18:21,786] {taskinstance.py:1420} INFO - Marking task as UP_FOR_RETRY. dag_id=update_data, task_id=update_data, execution_date=20231028T030612, start_date=20231030T001821, end_date=20231030T001821
[2023-10-30 00:18:21,800] {standard_task_runner.py:97} ERROR - Failed to execute job 79 for task update_data (Bash command failed. The command returned a non-zero exit code 2.; 528)
[2023-10-30 00:18:21,826] {local_task_job.py:156} INFO - Task exited with return code 1
[2023-10-30 00:18:21,871] {local_task_job.py:273} INFO - 0 downstream tasks scheduled from follow-on schedule check
