[2023-10-28 03:07:49,902] {taskinstance.py:1179} INFO - Dependencies all met for <TaskInstance: predict.predict manual__2023-10-28T03:07:48.555767+00:00 [queued]>
[2023-10-28 03:07:49,915] {taskinstance.py:1179} INFO - Dependencies all met for <TaskInstance: predict.predict manual__2023-10-28T03:07:48.555767+00:00 [queued]>
[2023-10-28 03:07:49,915] {taskinstance.py:1376} INFO - 
--------------------------------------------------------------------------------
[2023-10-28 03:07:49,916] {taskinstance.py:1377} INFO - Starting attempt 1 of 11
[2023-10-28 03:07:49,916] {taskinstance.py:1378} INFO - 
--------------------------------------------------------------------------------
[2023-10-28 03:07:49,936] {taskinstance.py:1397} INFO - Executing <Task(BashOperator): predict> on 2023-10-28 03:07:48.555767+00:00
[2023-10-28 03:07:49,941] {standard_task_runner.py:52} INFO - Started process 1241 to run task
[2023-10-28 03:07:49,944] {standard_task_runner.py:79} INFO - Running: ['***', 'tasks', 'run', 'predict', 'predict', 'manual__2023-10-28T03:07:48.555767+00:00', '--job-id', '57', '--raw', '--subdir', 'DAGS_FOLDER/predict_dag.py', '--cfg-path', '/tmp/tmpyerppgd5', '--error-file', '/tmp/tmpmnrq8k8h']
[2023-10-28 03:07:49,945] {standard_task_runner.py:80} INFO - Job 57: Subtask predict
[2023-10-28 03:07:55,020] {task_command.py:371} INFO - Running <TaskInstance: predict.predict manual__2023-10-28T03:07:48.555767+00:00 [running]> on host 9161207b4c08
[2023-10-28 03:07:55,105] {taskinstance.py:1591} INFO - Exporting the following env vars:
AIRFLOW_CTX_DAG_OWNER=Admin
AIRFLOW_CTX_DAG_ID=predict
AIRFLOW_CTX_TASK_ID=predict
AIRFLOW_CTX_EXECUTION_DATE=2023-10-28T03:07:48.555767+00:00
AIRFLOW_CTX_TRY_NUMBER=1
AIRFLOW_CTX_DAG_RUN_ID=manual__2023-10-28T03:07:48.555767+00:00
[2023-10-28 03:07:55,106] {subprocess.py:62} INFO - Tmp dir root location: 
 /tmp
[2023-10-28 03:07:55,107] {subprocess.py:74} INFO - Running command: ['bash', '-c', 'python3 predict.py']
[2023-10-28 03:07:55,117] {subprocess.py:85} INFO - Output:
[2023-10-28 03:07:55,237] {subprocess.py:92} INFO - python3: can't open file 'predict.py': [Errno 2] No such file or directory
[2023-10-28 03:07:55,241] {subprocess.py:96} INFO - Command exited with return code 2
[2023-10-28 03:07:55,259] {taskinstance.py:1909} ERROR - Task failed with exception
Traceback (most recent call last):
  File "/home/airflow/.local/lib/python3.7/site-packages/airflow/operators/bash.py", line 195, in execute
    f'Bash command failed. The command returned a non-zero exit code {result.exit_code}.'
airflow.exceptions.AirflowException: Bash command failed. The command returned a non-zero exit code 2.
[2023-10-28 03:07:55,263] {taskinstance.py:1420} INFO - Marking task as UP_FOR_RETRY. dag_id=predict, task_id=predict, execution_date=20231028T030748, start_date=20231028T030749, end_date=20231028T030755
[2023-10-28 03:07:55,276] {standard_task_runner.py:97} ERROR - Failed to execute job 57 for task predict (Bash command failed. The command returned a non-zero exit code 2.; 1241)
[2023-10-28 03:07:55,303] {local_task_job.py:156} INFO - Task exited with return code 1
[2023-10-28 03:07:55,333] {local_task_job.py:273} INFO - 0 downstream tasks scheduled from follow-on schedule check
