[2023-10-27 08:58:46,208] {taskinstance.py:1179} INFO - Dependencies all met for <TaskInstance: my_dag.run_my_python_script_task scheduled__2023-10-23T00:00:00+00:00 [queued]>
[2023-10-27 08:58:46,221] {taskinstance.py:1179} INFO - Dependencies all met for <TaskInstance: my_dag.run_my_python_script_task scheduled__2023-10-23T00:00:00+00:00 [queued]>
[2023-10-27 08:58:46,221] {taskinstance.py:1376} INFO - 
--------------------------------------------------------------------------------
[2023-10-27 08:58:46,221] {taskinstance.py:1377} INFO - Starting attempt 2 of 11
[2023-10-27 08:58:46,221] {taskinstance.py:1378} INFO - 
--------------------------------------------------------------------------------
[2023-10-27 08:58:46,236] {taskinstance.py:1397} INFO - Executing <Task(BashOperator): run_my_python_script_task> on 2023-10-23 00:00:00+00:00
[2023-10-27 08:58:46,241] {standard_task_runner.py:52} INFO - Started process 234 to run task
[2023-10-27 08:58:46,245] {standard_task_runner.py:79} INFO - Running: ['***', 'tasks', 'run', 'my_dag', 'run_my_python_script_task', 'scheduled__2023-10-23T00:00:00+00:00', '--job-id', '22', '--raw', '--subdir', 'DAGS_FOLDER/update_data_dag.py', '--cfg-path', '/tmp/tmpwa2o0lrr', '--error-file', '/tmp/tmpim69n3ju']
[2023-10-27 08:58:46,245] {standard_task_runner.py:80} INFO - Job 22: Subtask run_my_python_script_task
[2023-10-27 08:58:51,324] {task_command.py:371} INFO - Running <TaskInstance: my_dag.run_my_python_script_task scheduled__2023-10-23T00:00:00+00:00 [running]> on host 9161207b4c08
[2023-10-27 08:58:51,417] {taskinstance.py:1591} INFO - Exporting the following env vars:
AIRFLOW_CTX_DAG_OWNER=Admin
AIRFLOW_CTX_DAG_ID=my_dag
AIRFLOW_CTX_TASK_ID=run_my_python_script_task
AIRFLOW_CTX_EXECUTION_DATE=2023-10-23T00:00:00+00:00
AIRFLOW_CTX_TRY_NUMBER=2
AIRFLOW_CTX_DAG_RUN_ID=scheduled__2023-10-23T00:00:00+00:00
[2023-10-27 08:58:51,419] {subprocess.py:62} INFO - Tmp dir root location: 
 /tmp
[2023-10-27 08:58:51,419] {subprocess.py:74} INFO - Running command: ['bash', '-c', 'docker exec -it update_data:3.9.18 python3 /home/ubuntu/mlopspipeline/docker/update_python/app/update_data.py']
[2023-10-27 08:58:51,433] {subprocess.py:85} INFO - Output:
[2023-10-27 08:58:51,435] {subprocess.py:92} INFO - bash: line 1: docker: command not found
[2023-10-27 08:58:51,436] {subprocess.py:96} INFO - Command exited with return code 127
[2023-10-27 08:58:51,457] {taskinstance.py:1909} ERROR - Task failed with exception
Traceback (most recent call last):
  File "/home/airflow/.local/lib/python3.7/site-packages/airflow/operators/bash.py", line 195, in execute
    f'Bash command failed. The command returned a non-zero exit code {result.exit_code}.'
airflow.exceptions.AirflowException: Bash command failed. The command returned a non-zero exit code 127.
[2023-10-27 08:58:51,462] {taskinstance.py:1420} INFO - Marking task as UP_FOR_RETRY. dag_id=my_dag, task_id=run_my_python_script_task, execution_date=20231023T000000, start_date=20231027T085846, end_date=20231027T085851
[2023-10-27 08:58:51,478] {standard_task_runner.py:97} ERROR - Failed to execute job 22 for task run_my_python_script_task (Bash command failed. The command returned a non-zero exit code 127.; 234)
[2023-10-27 08:58:51,493] {local_task_job.py:156} INFO - Task exited with return code 1
[2023-10-27 08:58:51,526] {local_task_job.py:273} INFO - 0 downstream tasks scheduled from follow-on schedule check
