[2023-10-28 02:02:45,307] {taskinstance.py:1179} INFO - Dependencies all met for <TaskInstance: my_dag.run_my_python_script_task scheduled__2023-10-23T00:00:00+00:00 [queued]>
[2023-10-28 02:02:45,320] {taskinstance.py:1179} INFO - Dependencies all met for <TaskInstance: my_dag.run_my_python_script_task scheduled__2023-10-23T00:00:00+00:00 [queued]>
[2023-10-28 02:02:45,320] {taskinstance.py:1376} INFO - 
--------------------------------------------------------------------------------
[2023-10-28 02:02:45,320] {taskinstance.py:1377} INFO - Starting attempt 10 of 11
[2023-10-28 02:02:45,320] {taskinstance.py:1378} INFO - 
--------------------------------------------------------------------------------
[2023-10-28 02:02:45,337] {taskinstance.py:1397} INFO - Executing <Task(BashOperator): run_my_python_script_task> on 2023-10-23 00:00:00+00:00
[2023-10-28 02:02:45,342] {standard_task_runner.py:52} INFO - Started process 891 to run task
[2023-10-28 02:02:45,346] {standard_task_runner.py:79} INFO - Running: ['***', 'tasks', 'run', 'my_dag', 'run_my_python_script_task', 'scheduled__2023-10-23T00:00:00+00:00', '--job-id', '32', '--raw', '--subdir', 'DAGS_FOLDER/update_data_dag.py', '--cfg-path', '/tmp/tmpfs2sc7zq', '--error-file', '/tmp/tmpdg5luk67']
[2023-10-28 02:02:45,346] {standard_task_runner.py:80} INFO - Job 32: Subtask run_my_python_script_task
[2023-10-28 02:02:45,421] {task_command.py:371} INFO - Running <TaskInstance: my_dag.run_my_python_script_task scheduled__2023-10-23T00:00:00+00:00 [running]> on host 9161207b4c08
[2023-10-28 02:02:45,503] {taskinstance.py:1591} INFO - Exporting the following env vars:
AIRFLOW_CTX_DAG_OWNER=Admin
AIRFLOW_CTX_DAG_ID=my_dag
AIRFLOW_CTX_TASK_ID=run_my_python_script_task
AIRFLOW_CTX_EXECUTION_DATE=2023-10-23T00:00:00+00:00
AIRFLOW_CTX_TRY_NUMBER=10
AIRFLOW_CTX_DAG_RUN_ID=scheduled__2023-10-23T00:00:00+00:00
[2023-10-28 02:02:45,504] {subprocess.py:62} INFO - Tmp dir root location: 
 /tmp
[2023-10-28 02:02:45,505] {subprocess.py:74} INFO - Running command: ['bash', '-c', 'docker exec -it update_data:3.9.18 python3 /home/ubuntu/mlopspipeline/docker/update_python/app/update_data.py']
[2023-10-28 02:02:45,514] {subprocess.py:85} INFO - Output:
[2023-10-28 02:02:45,516] {subprocess.py:92} INFO - bash: line 1: docker: command not found
[2023-10-28 02:02:45,517] {subprocess.py:96} INFO - Command exited with return code 127
[2023-10-28 02:02:45,535] {taskinstance.py:1909} ERROR - Task failed with exception
Traceback (most recent call last):
  File "/home/airflow/.local/lib/python3.7/site-packages/airflow/operators/bash.py", line 195, in execute
    f'Bash command failed. The command returned a non-zero exit code {result.exit_code}.'
airflow.exceptions.AirflowException: Bash command failed. The command returned a non-zero exit code 127.
[2023-10-28 02:02:45,539] {taskinstance.py:1420} INFO - Marking task as UP_FOR_RETRY. dag_id=my_dag, task_id=run_my_python_script_task, execution_date=20231023T000000, start_date=20231028T020245, end_date=20231028T020245
[2023-10-28 02:02:45,555] {standard_task_runner.py:97} ERROR - Failed to execute job 32 for task run_my_python_script_task (Bash command failed. The command returned a non-zero exit code 127.; 891)
[2023-10-28 02:02:45,597] {local_task_job.py:156} INFO - Task exited with return code 1
[2023-10-28 02:02:45,634] {local_task_job.py:273} INFO - 0 downstream tasks scheduled from follow-on schedule check
