[2023-10-30 00:09:17,244] {taskinstance.py:1179} INFO - Dependencies all met for <TaskInstance: predict.predict scheduled__2023-10-26T15:00:00+00:00 [queued]>
[2023-10-30 00:09:17,279] {taskinstance.py:1179} INFO - Dependencies all met for <TaskInstance: predict.predict scheduled__2023-10-26T15:00:00+00:00 [queued]>
[2023-10-30 00:09:17,279] {taskinstance.py:1376} INFO - 
--------------------------------------------------------------------------------
[2023-10-30 00:09:17,279] {taskinstance.py:1377} INFO - Starting attempt 1 of 11
[2023-10-30 00:09:17,279] {taskinstance.py:1378} INFO - 
--------------------------------------------------------------------------------
[2023-10-30 00:09:17,320] {taskinstance.py:1397} INFO - Executing <Task(BashOperator): predict> on 2023-10-26 15:00:00+00:00
[2023-10-30 00:09:17,324] {standard_task_runner.py:52} INFO - Started process 67 to run task
[2023-10-30 00:09:17,337] {standard_task_runner.py:79} INFO - Running: ['***', 'tasks', 'run', 'predict', 'predict', 'scheduled__2023-10-26T15:00:00+00:00', '--job-id', '66', '--raw', '--subdir', 'DAGS_FOLDER/predict_dag.py', '--cfg-path', '/tmp/tmp25xh00tk', '--error-file', '/tmp/tmpy7gj6poe']
[2023-10-30 00:09:17,338] {standard_task_runner.py:80} INFO - Job 66: Subtask predict
[2023-10-30 00:09:17,655] {task_command.py:371} INFO - Running <TaskInstance: predict.predict scheduled__2023-10-26T15:00:00+00:00 [running]> on host 9161207b4c08
[2023-10-30 00:09:17,992] {taskinstance.py:1591} INFO - Exporting the following env vars:
AIRFLOW_CTX_DAG_OWNER=Admin
AIRFLOW_CTX_DAG_ID=predict
AIRFLOW_CTX_TASK_ID=predict
AIRFLOW_CTX_EXECUTION_DATE=2023-10-26T15:00:00+00:00
AIRFLOW_CTX_TRY_NUMBER=1
AIRFLOW_CTX_DAG_RUN_ID=scheduled__2023-10-26T15:00:00+00:00
[2023-10-30 00:09:17,993] {subprocess.py:62} INFO - Tmp dir root location: 
 /tmp
[2023-10-30 00:09:17,993] {subprocess.py:74} INFO - Running command: ['bash', '-c', 'python3 predict.py']
[2023-10-30 00:09:18,063] {subprocess.py:85} INFO - Output:
[2023-10-30 00:09:18,627] {subprocess.py:92} INFO - python3: can't open file 'predict.py': [Errno 2] No such file or directory
[2023-10-30 00:09:18,637] {subprocess.py:96} INFO - Command exited with return code 2
[2023-10-30 00:09:18,693] {taskinstance.py:1909} ERROR - Task failed with exception
Traceback (most recent call last):
  File "/home/airflow/.local/lib/python3.7/site-packages/airflow/operators/bash.py", line 195, in execute
    f'Bash command failed. The command returned a non-zero exit code {result.exit_code}.'
airflow.exceptions.AirflowException: Bash command failed. The command returned a non-zero exit code 2.
[2023-10-30 00:09:18,703] {taskinstance.py:1420} INFO - Marking task as UP_FOR_RETRY. dag_id=predict, task_id=predict, execution_date=20231026T150000, start_date=20231030T000917, end_date=20231030T000918
[2023-10-30 00:09:18,754] {standard_task_runner.py:97} ERROR - Failed to execute job 66 for task predict (Bash command failed. The command returned a non-zero exit code 2.; 67)
[2023-10-30 00:09:18,804] {local_task_job.py:156} INFO - Task exited with return code 1
[2023-10-30 00:09:18,879] {local_task_job.py:273} INFO - 0 downstream tasks scheduled from follow-on schedule check
