[2023-10-27 08:00:32,078] {taskinstance.py:1179} INFO - Dependencies all met for <TaskInstance: update_data_dag.update_data_task scheduled__2023-10-26T15:30:00+00:00 [queued]>
[2023-10-27 08:00:32,089] {taskinstance.py:1179} INFO - Dependencies all met for <TaskInstance: update_data_dag.update_data_task scheduled__2023-10-26T15:30:00+00:00 [queued]>
[2023-10-27 08:00:32,089] {taskinstance.py:1376} INFO - 
--------------------------------------------------------------------------------
[2023-10-27 08:00:32,089] {taskinstance.py:1377} INFO - Starting attempt 2 of 2
[2023-10-27 08:00:32,089] {taskinstance.py:1378} INFO - 
--------------------------------------------------------------------------------
[2023-10-27 08:00:32,107] {taskinstance.py:1397} INFO - Executing <Task(DockerOperator): update_data_task> on 2023-10-26 15:30:00+00:00
[2023-10-27 08:00:32,112] {standard_task_runner.py:52} INFO - Started process 280 to run task
[2023-10-27 08:00:32,117] {standard_task_runner.py:79} INFO - Running: ['***', 'tasks', 'run', 'update_data_dag', 'update_data_task', 'scheduled__2023-10-26T15:30:00+00:00', '--job-id', '16', '--raw', '--subdir', 'DAGS_FOLDER/update_data_dag.py', '--cfg-path', '/tmp/tmpvm8raygi', '--error-file', '/tmp/tmpx_yf9g18']
[2023-10-27 08:00:32,117] {standard_task_runner.py:80} INFO - Job 16: Subtask update_data_task
[2023-10-27 08:00:32,189] {task_command.py:371} INFO - Running <TaskInstance: update_data_dag.update_data_task scheduled__2023-10-26T15:30:00+00:00 [running]> on host 9161207b4c08
[2023-10-27 08:00:32,271] {taskinstance.py:1591} INFO - Exporting the following env vars:
AIRFLOW_CTX_DAG_OWNER=admin
AIRFLOW_CTX_DAG_ID=update_data_dag
AIRFLOW_CTX_TASK_ID=update_data_task
AIRFLOW_CTX_EXECUTION_DATE=2023-10-26T15:30:00+00:00
AIRFLOW_CTX_TRY_NUMBER=2
AIRFLOW_CTX_DAG_RUN_ID=scheduled__2023-10-26T15:30:00+00:00
[2023-10-27 08:00:32,277] {taskinstance.py:1909} ERROR - Task failed with exception
Traceback (most recent call last):
  File "/home/airflow/.local/lib/python3.7/site-packages/urllib3/connectionpool.py", line 710, in urlopen
    chunked=chunked,
  File "/home/airflow/.local/lib/python3.7/site-packages/urllib3/connectionpool.py", line 398, in _make_request
    conn.request(method, url, **httplib_request_kw)
  File "/usr/local/lib/python3.7/http/client.py", line 1281, in request
    self._send_request(method, url, body, headers, encode_chunked)
  File "/usr/local/lib/python3.7/http/client.py", line 1327, in _send_request
    self.endheaders(body, encode_chunked=encode_chunked)
  File "/usr/local/lib/python3.7/http/client.py", line 1276, in endheaders
    self._send_output(message_body, encode_chunked=encode_chunked)
  File "/usr/local/lib/python3.7/http/client.py", line 1036, in _send_output
    self.send(msg)
  File "/usr/local/lib/python3.7/http/client.py", line 976, in send
    self.connect()
  File "/home/airflow/.local/lib/python3.7/site-packages/docker/transport/unixconn.py", line 30, in connect
    sock.connect(self.unix_socket)
FileNotFoundError: [Errno 2] No such file or directory

During handling of the above exception, another exception occurred:

Traceback (most recent call last):
  File "/home/airflow/.local/lib/python3.7/site-packages/requests/adapters.py", line 499, in send
    timeout=timeout,
  File "/home/airflow/.local/lib/python3.7/site-packages/urllib3/connectionpool.py", line 786, in urlopen
    method, url, error=e, _pool=self, _stacktrace=sys.exc_info()[2]
  File "/home/airflow/.local/lib/python3.7/site-packages/urllib3/util/retry.py", line 550, in increment
    raise six.reraise(type(error), error, _stacktrace)
  File "/home/airflow/.local/lib/python3.7/site-packages/urllib3/packages/six.py", line 769, in reraise
    raise value.with_traceback(tb)
  File "/home/airflow/.local/lib/python3.7/site-packages/urllib3/connectionpool.py", line 710, in urlopen
    chunked=chunked,
  File "/home/airflow/.local/lib/python3.7/site-packages/urllib3/connectionpool.py", line 398, in _make_request
    conn.request(method, url, **httplib_request_kw)
  File "/usr/local/lib/python3.7/http/client.py", line 1281, in request
    self._send_request(method, url, body, headers, encode_chunked)
  File "/usr/local/lib/python3.7/http/client.py", line 1327, in _send_request
    self.endheaders(body, encode_chunked=encode_chunked)
  File "/usr/local/lib/python3.7/http/client.py", line 1276, in endheaders
    self._send_output(message_body, encode_chunked=encode_chunked)
  File "/usr/local/lib/python3.7/http/client.py", line 1036, in _send_output
    self.send(msg)
  File "/usr/local/lib/python3.7/http/client.py", line 976, in send
    self.connect()
  File "/home/airflow/.local/lib/python3.7/site-packages/docker/transport/unixconn.py", line 30, in connect
    sock.connect(self.unix_socket)
urllib3.exceptions.ProtocolError: ('Connection aborted.', FileNotFoundError(2, 'No such file or directory'))

During handling of the above exception, another exception occurred:

Traceback (most recent call last):
  File "/home/airflow/.local/lib/python3.7/site-packages/docker/api/client.py", line 214, in _retrieve_server_version
    return self.version(api_version=False)["ApiVersion"]
  File "/home/airflow/.local/lib/python3.7/site-packages/docker/api/daemon.py", line 181, in version
    return self._result(self._get(url), json=True)
  File "/home/airflow/.local/lib/python3.7/site-packages/docker/utils/decorators.py", line 46, in inner
    return f(self, *args, **kwargs)
  File "/home/airflow/.local/lib/python3.7/site-packages/docker/api/client.py", line 237, in _get
    return self.get(url, **self._set_request_timeout(kwargs))
  File "/home/airflow/.local/lib/python3.7/site-packages/requests/sessions.py", line 600, in get
    return self.request("GET", url, **kwargs)
  File "/home/airflow/.local/lib/python3.7/site-packages/requests/sessions.py", line 587, in request
    resp = self.send(prep, **send_kwargs)
  File "/home/airflow/.local/lib/python3.7/site-packages/requests/sessions.py", line 701, in send
    r = adapter.send(request, **kwargs)
  File "/home/airflow/.local/lib/python3.7/site-packages/requests/adapters.py", line 547, in send
    raise ConnectionError(err, request=request)
requests.exceptions.ConnectionError: ('Connection aborted.', FileNotFoundError(2, 'No such file or directory'))

During handling of the above exception, another exception occurred:

Traceback (most recent call last):
  File "/home/airflow/.local/lib/python3.7/site-packages/airflow/providers/docker/operators/docker.py", line 366, in execute
    self.cli = self._get_cli()
  File "/home/airflow/.local/lib/python3.7/site-packages/airflow/providers/docker/operators/docker.py", line 397, in _get_cli
    base_url=self.docker_url, version=self.api_version, tls=tls_config, timeout=self.timeout
  File "/home/airflow/.local/lib/python3.7/site-packages/docker/api/client.py", line 197, in __init__
    self._version = self._retrieve_server_version()
  File "/home/airflow/.local/lib/python3.7/site-packages/docker/api/client.py", line 222, in _retrieve_server_version
    f'Error while fetching server API version: {e}'
docker.errors.DockerException: Error while fetching server API version: ('Connection aborted.', FileNotFoundError(2, 'No such file or directory'))
[2023-10-27 08:00:32,289] {taskinstance.py:1420} INFO - Marking task as FAILED. dag_id=update_data_dag, task_id=update_data_task, execution_date=20231026T153000, start_date=20231027T080032, end_date=20231027T080032
[2023-10-27 08:00:32,301] {standard_task_runner.py:97} ERROR - Failed to execute job 16 for task update_data_task (Error while fetching server API version: ('Connection aborted.', FileNotFoundError(2, 'No such file or directory')); 280)
[2023-10-27 08:00:32,333] {local_task_job.py:156} INFO - Task exited with return code 1
[2023-10-27 08:00:32,370] {local_task_job.py:273} INFO - 0 downstream tasks scheduled from follow-on schedule check
